<?xml version="1.0" encoding="UTF-8"?>
<robot generator="Robot 4.1.3 (Python 3.10.2 on win32)" generated="20220319 18:20:39.464" rpa="false" schemaversion="2">
<suite id="s1" name="Verify Emergency Contact Suite" source="E:\LTTS\robort\robot_framework\my_info_suite\verify_emergency_contact_suite.robot">
<test id="s1-t1" name="Verify Add Emergency Contact Test">
<status status="FAIL" starttime="20220319 18:21:32.345" endtime="20220319 18:21:32.356">Test case contains no keywords.</status>
</test>
<doc>This suite handles test case related to emergency contact</doc>
<status status="FAIL" starttime="20220319 18:20:39.466" endtime="20220319 18:21:32.364"/>
</suite>
<statistics>
<total>
<stat pass="0" fail="1" skip="0">All Tests</stat>
</total>
<tag>
</tag>
<suite>
<stat pass="0" fail="1" skip="0" id="s1" name="Verify Emergency Contact Suite">Verify Emergency Contact Suite</stat>
</suite>
</statistics>
<errors>
<msg timestamp="20220319 18:21:32.085" level="ERROR">[ DataDriver ] Error in robot file:
  File "E:\LTTS\robort\robot_framework\my_info_suite\verify_emergency_contact_suite.robot", line 0</msg>
<msg timestamp="20220319 18:21:32.088" level="ERROR">In source file:
  File "E:\LTTS\robort\robot_framework\my_info_suite\../test_data/orange_data.xlsx", line 0</msg>
<msg timestamp="20220319 18:21:32.342" level="ERROR">Calling method '_start_suite' of listener 'DataDriver' failed: ValueError: Worksheet named 'AddEmergencyContact' not found</msg>
</errors>
</robot>
